try:
    print(x)
except:
    print("Something went wrong")
finally:
    print("Try_Except blocks are successfully executed")